2024-09-27 14:25:47,550 ERROR 예외 발생
Traceback (most recent call last):
  File "/Users/sunningkim/Documents/ml/projects/2_multi_head_attention_sentiment_analysis.py", line 245, in <module>
    for data in train_loader:
  File "/Users/sunningkim/Documents/ml/projects/venv/lib/python3.9/site-packages/torch/utils/data/dataloader.py", line 440, in __iter__
    return self._get_iterator()
  File "/Users/sunningkim/Documents/ml/projects/venv/lib/python3.9/site-packages/torch/utils/data/dataloader.py", line 388, in _get_iterator
    return _MultiProcessingDataLoaderIter(self)
  File "/Users/sunningkim/Documents/ml/projects/venv/lib/python3.9/site-packages/torch/utils/data/dataloader.py", line 1038, in __init__
    w.start()
  File "/Library/Developer/CommandLineTools/Library/Frameworks/Python3.framework/Versions/3.9/lib/python3.9/multiprocessing/process.py", line 121, in start
    self._popen = self._Popen(self)
  File "/Library/Developer/CommandLineTools/Library/Frameworks/Python3.framework/Versions/3.9/lib/python3.9/multiprocessing/context.py", line 224, in _Popen
    return _default_context.get_context().Process._Popen(process_obj)
  File "/Library/Developer/CommandLineTools/Library/Frameworks/Python3.framework/Versions/3.9/lib/python3.9/multiprocessing/context.py", line 284, in _Popen
    return Popen(process_obj)
  File "/Library/Developer/CommandLineTools/Library/Frameworks/Python3.framework/Versions/3.9/lib/python3.9/multiprocessing/popen_spawn_posix.py", line 32, in __init__
    super().__init__(process_obj)
  File "/Library/Developer/CommandLineTools/Library/Frameworks/Python3.framework/Versions/3.9/lib/python3.9/multiprocessing/popen_fork.py", line 19, in __init__
    self._launch(process_obj)
  File "/Library/Developer/CommandLineTools/Library/Frameworks/Python3.framework/Versions/3.9/lib/python3.9/multiprocessing/popen_spawn_posix.py", line 42, in _launch
    prep_data = spawn.get_preparation_data(process_obj._name)
  File "/Library/Developer/CommandLineTools/Library/Frameworks/Python3.framework/Versions/3.9/lib/python3.9/multiprocessing/spawn.py", line 154, in get_preparation_data
    _check_not_importing_main()
  File "/Library/Developer/CommandLineTools/Library/Frameworks/Python3.framework/Versions/3.9/lib/python3.9/multiprocessing/spawn.py", line 134, in _check_not_importing_main
    raise RuntimeError('''
RuntimeError: 
        An attempt has been made to start a new process before the
        current process has finished its bootstrapping phase.

        This probably means that you are not using fork to start your
        child processes and you have forgotten to use the proper idiom
        in the main module:

            if __name__ == '__main__':
                freeze_support()
                ...

        The "freeze_support()" line can be omitted if the program
        is not going to be frozen to produce an executable.
2024-09-27 14:25:47,800 ERROR 예외 발생
Traceback (most recent call last):
  File "/Users/sunningkim/Documents/ml/projects/2_multi_head_attention_sentiment_analysis.py", line 245, in <module>
    for data in train_loader:
  File "/Users/sunningkim/Documents/ml/projects/venv/lib/python3.9/site-packages/torch/utils/data/dataloader.py", line 440, in __iter__
    return self._get_iterator()
  File "/Users/sunningkim/Documents/ml/projects/venv/lib/python3.9/site-packages/torch/utils/data/dataloader.py", line 388, in _get_iterator
    return _MultiProcessingDataLoaderIter(self)
  File "/Users/sunningkim/Documents/ml/projects/venv/lib/python3.9/site-packages/torch/utils/data/dataloader.py", line 1038, in __init__
    w.start()
  File "/Library/Developer/CommandLineTools/Library/Frameworks/Python3.framework/Versions/3.9/lib/python3.9/multiprocessing/process.py", line 121, in start
    self._popen = self._Popen(self)
  File "/Library/Developer/CommandLineTools/Library/Frameworks/Python3.framework/Versions/3.9/lib/python3.9/multiprocessing/context.py", line 224, in _Popen
    return _default_context.get_context().Process._Popen(process_obj)
  File "/Library/Developer/CommandLineTools/Library/Frameworks/Python3.framework/Versions/3.9/lib/python3.9/multiprocessing/context.py", line 284, in _Popen
    return Popen(process_obj)
  File "/Library/Developer/CommandLineTools/Library/Frameworks/Python3.framework/Versions/3.9/lib/python3.9/multiprocessing/popen_spawn_posix.py", line 32, in __init__
    super().__init__(process_obj)
  File "/Library/Developer/CommandLineTools/Library/Frameworks/Python3.framework/Versions/3.9/lib/python3.9/multiprocessing/popen_fork.py", line 19, in __init__
    self._launch(process_obj)
  File "/Library/Developer/CommandLineTools/Library/Frameworks/Python3.framework/Versions/3.9/lib/python3.9/multiprocessing/popen_spawn_posix.py", line 42, in _launch
    prep_data = spawn.get_preparation_data(process_obj._name)
  File "/Library/Developer/CommandLineTools/Library/Frameworks/Python3.framework/Versions/3.9/lib/python3.9/multiprocessing/spawn.py", line 154, in get_preparation_data
    _check_not_importing_main()
  File "/Library/Developer/CommandLineTools/Library/Frameworks/Python3.framework/Versions/3.9/lib/python3.9/multiprocessing/spawn.py", line 134, in _check_not_importing_main
    raise RuntimeError('''
RuntimeError: 
        An attempt has been made to start a new process before the
        current process has finished its bootstrapping phase.

        This probably means that you are not using fork to start your
        child processes and you have forgotten to use the proper idiom
        in the main module:

            if __name__ == '__main__':
                freeze_support()
                ...

        The "freeze_support()" line can be omitted if the program
        is not going to be frozen to produce an executable.
2024-09-27 14:25:48,459 ERROR 예외 발생
Traceback (most recent call last):
  File "/Users/sunningkim/Documents/ml/projects/venv/lib/python3.9/site-packages/torch/utils/data/dataloader.py", line 1131, in _try_get_data
    data = self._data_queue.get(timeout=timeout)
  File "/Library/Developer/CommandLineTools/Library/Frameworks/Python3.framework/Versions/3.9/lib/python3.9/multiprocessing/queues.py", line 113, in get
    if not self._poll(timeout):
  File "/Library/Developer/CommandLineTools/Library/Frameworks/Python3.framework/Versions/3.9/lib/python3.9/multiprocessing/connection.py", line 262, in poll
    return self._poll(timeout)
  File "/Library/Developer/CommandLineTools/Library/Frameworks/Python3.framework/Versions/3.9/lib/python3.9/multiprocessing/connection.py", line 429, in _poll
    r = wait([self], timeout)
  File "/Library/Developer/CommandLineTools/Library/Frameworks/Python3.framework/Versions/3.9/lib/python3.9/multiprocessing/connection.py", line 936, in wait
    ready = selector.select(timeout)
  File "/Library/Developer/CommandLineTools/Library/Frameworks/Python3.framework/Versions/3.9/lib/python3.9/selectors.py", line 416, in select
    fd_event_list = self._selector.poll(timeout)
  File "/Users/sunningkim/Documents/ml/projects/venv/lib/python3.9/site-packages/torch/utils/data/_utils/signal_handling.py", line 67, in handler
    _error_if_any_worker_fails()
RuntimeError: DataLoader worker (pid 94580) exited unexpectedly with exit code 1. Details are lost due to multiprocessing. Rerunning with num_workers=0 may give better error trace.

The above exception was the direct cause of the following exception:

Traceback (most recent call last):
  File "/Users/sunningkim/Documents/ml/projects/2_multi_head_attention_sentiment_analysis.py", line 245, in <module>
    for data in train_loader:
  File "/Users/sunningkim/Documents/ml/projects/venv/lib/python3.9/site-packages/torch/utils/data/dataloader.py", line 630, in __next__
    data = self._next_data()
  File "/Users/sunningkim/Documents/ml/projects/venv/lib/python3.9/site-packages/torch/utils/data/dataloader.py", line 1327, in _next_data
    idx, data = self._get_data()
  File "/Users/sunningkim/Documents/ml/projects/venv/lib/python3.9/site-packages/torch/utils/data/dataloader.py", line 1293, in _get_data
    success, data = self._try_get_data()
  File "/Users/sunningkim/Documents/ml/projects/venv/lib/python3.9/site-packages/torch/utils/data/dataloader.py", line 1144, in _try_get_data
    raise RuntimeError(f'DataLoader worker (pid(s) {pids_str}) exited unexpectedly') from e
RuntimeError: DataLoader worker (pid(s) 94580) exited unexpectedly
2024-09-27 14:25:48,781 ERROR 예외 발생
Traceback (most recent call last):
  File "/Users/sunningkim/Documents/ml/projects/2_multi_head_attention_sentiment_analysis.py", line 245, in <module>
    for data in train_loader:
  File "/Users/sunningkim/Documents/ml/projects/venv/lib/python3.9/site-packages/torch/utils/data/dataloader.py", line 440, in __iter__
    return self._get_iterator()
  File "/Users/sunningkim/Documents/ml/projects/venv/lib/python3.9/site-packages/torch/utils/data/dataloader.py", line 388, in _get_iterator
    return _MultiProcessingDataLoaderIter(self)
  File "/Users/sunningkim/Documents/ml/projects/venv/lib/python3.9/site-packages/torch/utils/data/dataloader.py", line 1038, in __init__
    w.start()
  File "/Library/Developer/CommandLineTools/Library/Frameworks/Python3.framework/Versions/3.9/lib/python3.9/multiprocessing/process.py", line 121, in start
    self._popen = self._Popen(self)
  File "/Library/Developer/CommandLineTools/Library/Frameworks/Python3.framework/Versions/3.9/lib/python3.9/multiprocessing/context.py", line 224, in _Popen
    return _default_context.get_context().Process._Popen(process_obj)
  File "/Library/Developer/CommandLineTools/Library/Frameworks/Python3.framework/Versions/3.9/lib/python3.9/multiprocessing/context.py", line 284, in _Popen
    return Popen(process_obj)
  File "/Library/Developer/CommandLineTools/Library/Frameworks/Python3.framework/Versions/3.9/lib/python3.9/multiprocessing/popen_spawn_posix.py", line 32, in __init__
    super().__init__(process_obj)
  File "/Library/Developer/CommandLineTools/Library/Frameworks/Python3.framework/Versions/3.9/lib/python3.9/multiprocessing/popen_fork.py", line 19, in __init__
    self._launch(process_obj)
  File "/Library/Developer/CommandLineTools/Library/Frameworks/Python3.framework/Versions/3.9/lib/python3.9/multiprocessing/popen_spawn_posix.py", line 42, in _launch
    prep_data = spawn.get_preparation_data(process_obj._name)
  File "/Library/Developer/CommandLineTools/Library/Frameworks/Python3.framework/Versions/3.9/lib/python3.9/multiprocessing/spawn.py", line 154, in get_preparation_data
    _check_not_importing_main()
  File "/Library/Developer/CommandLineTools/Library/Frameworks/Python3.framework/Versions/3.9/lib/python3.9/multiprocessing/spawn.py", line 134, in _check_not_importing_main
    raise RuntimeError('''
RuntimeError: 
        An attempt has been made to start a new process before the
        current process has finished its bootstrapping phase.

        This probably means that you are not using fork to start your
        child processes and you have forgotten to use the proper idiom
        in the main module:

            if __name__ == '__main__':
                freeze_support()
                ...

        The "freeze_support()" line can be omitted if the program
        is not going to be frozen to produce an executable.
2024-09-27 14:25:51,293 ERROR 예외 발생
Traceback (most recent call last):
  File "/Users/sunningkim/Documents/ml/projects/2_multi_head_attention_sentiment_analysis.py", line 245, in <module>
    for data in train_loader:
  File "/Users/sunningkim/Documents/ml/projects/venv/lib/python3.9/site-packages/torch/utils/data/dataloader.py", line 440, in __iter__
    return self._get_iterator()
  File "/Users/sunningkim/Documents/ml/projects/venv/lib/python3.9/site-packages/torch/utils/data/dataloader.py", line 388, in _get_iterator
    return _MultiProcessingDataLoaderIter(self)
  File "/Users/sunningkim/Documents/ml/projects/venv/lib/python3.9/site-packages/torch/utils/data/dataloader.py", line 1038, in __init__
    w.start()
  File "/Library/Developer/CommandLineTools/Library/Frameworks/Python3.framework/Versions/3.9/lib/python3.9/multiprocessing/process.py", line 121, in start
    self._popen = self._Popen(self)
  File "/Library/Developer/CommandLineTools/Library/Frameworks/Python3.framework/Versions/3.9/lib/python3.9/multiprocessing/context.py", line 224, in _Popen
    return _default_context.get_context().Process._Popen(process_obj)
  File "/Library/Developer/CommandLineTools/Library/Frameworks/Python3.framework/Versions/3.9/lib/python3.9/multiprocessing/context.py", line 284, in _Popen
    return Popen(process_obj)
  File "/Library/Developer/CommandLineTools/Library/Frameworks/Python3.framework/Versions/3.9/lib/python3.9/multiprocessing/popen_spawn_posix.py", line 32, in __init__
    super().__init__(process_obj)
  File "/Library/Developer/CommandLineTools/Library/Frameworks/Python3.framework/Versions/3.9/lib/python3.9/multiprocessing/popen_fork.py", line 19, in __init__
    self._launch(process_obj)
  File "/Library/Developer/CommandLineTools/Library/Frameworks/Python3.framework/Versions/3.9/lib/python3.9/multiprocessing/popen_spawn_posix.py", line 42, in _launch
    prep_data = spawn.get_preparation_data(process_obj._name)
  File "/Library/Developer/CommandLineTools/Library/Frameworks/Python3.framework/Versions/3.9/lib/python3.9/multiprocessing/spawn.py", line 154, in get_preparation_data
    _check_not_importing_main()
  File "/Library/Developer/CommandLineTools/Library/Frameworks/Python3.framework/Versions/3.9/lib/python3.9/multiprocessing/spawn.py", line 134, in _check_not_importing_main
    raise RuntimeError('''
RuntimeError: 
        An attempt has been made to start a new process before the
        current process has finished its bootstrapping phase.

        This probably means that you are not using fork to start your
        child processes and you have forgotten to use the proper idiom
        in the main module:

            if __name__ == '__main__':
                freeze_support()
                ...

        The "freeze_support()" line can be omitted if the program
        is not going to be frozen to produce an executable.
2024-09-27 14:27:39,395 ERROR 예외 발생
Traceback (most recent call last):
  File "/Users/sunningkim/Documents/ml/projects/2_multi_head_attention_sentiment_analysis.py", line 249, in <module>
    inputs = torch.tensor(data['input_ids']).to(device)
TypeError: only integer tensors of a single element can be converted to an index
